{
 "cells": [
  {
   "cell_type": "markdown",
   "metadata": {},
   "source": [
    "**【Jupyter Notebookとしての注意】**\n",
    "+ 本ファイルはJupyter Notebook形式で記載するので 、(>>> や ...) といったプロンプトはプログラム例から削除しています。\n",
    "+ 対話形式では、式を入れると値が表示されますが、Jupyter Notebookでは、最後の結果しか表示されないため、プログラム例に適宜「print」を追加しています。\n",
    "+ print文で表示すると文字列の表現等が異なるため、プログラム例では、適宜、式に対して「repr」という関数を適用した結果をprintしています。"
   ]
  },
  {
   "cell_type": "markdown",
   "metadata": {},
   "source": [
    "# 8. エラーと例外\n",
    "これまでエラーメッセージについては簡単に触れるだけでしたが、チュートリアル中の例を自分で試していたら、実際にいくつかのエラーメッセージを見ていることでしょう。エラーには (少なくとも) 二つのはっきり異なる種類があります。それは 構文エラー (syntax error) と 例外 (exception) です。\n",
    "\n",
    "## 8.1. 構文エラー\n",
    "構文エラーは構文解析エラー (parsing error) としても知られており、Python を勉強している間に最もよく遭遇する問題の一つでしょう:"
   ]
  },
  {
   "cell_type": "code",
   "execution_count": 1,
   "metadata": {
    "collapsed": false
   },
   "outputs": [
    {
     "ename": "SyntaxError",
     "evalue": "invalid syntax (<ipython-input-1-f4b9dbd125c8>, line 1)",
     "output_type": "error",
     "traceback": [
      "\u001b[1;36m  File \u001b[1;32m\"<ipython-input-1-f4b9dbd125c8>\"\u001b[1;36m, line \u001b[1;32m1\u001b[0m\n\u001b[1;33m    while True print 'Hello world'\u001b[0m\n\u001b[1;37m                   ^\u001b[0m\n\u001b[1;31mSyntaxError\u001b[0m\u001b[1;31m:\u001b[0m invalid syntax\n"
     ]
    }
   ],
   "source": [
    "while True print 'Hello world'"
   ]
  },
  {
   "cell_type": "markdown",
   "metadata": {},
   "source": [
    "パーサは違反の起きている行を表示し、小さな「矢印」を表示して、行中でエラーが検出された最初の位置を示します。エラーは矢印の 直前の トークンでひき起こされています (または、少なくともそこで検出されています)。上記の例では、エラーは print で検出されています。コロン (':') がその前に無いからです。入力がスクリプトから来ている場合は、どこを見ればよいか分かるようにファイル名と行番号が出力されます。"
   ]
  },
  {
   "cell_type": "markdown",
   "metadata": {},
   "source": [
    "## 8.2. 例外\n",
    "たとえ文や式が構文的に正しくても、実行しようとしたときにエラーが発生するかもしれません。実行中に検出されたエラーは 例外 (exception) と呼ばれ、常に致命的とは限りません。これから、Python プログラムで例外をどのように扱うかを学んでいきます。ほとんどの例外はプログラムで処理されず、以下に示されるようなメッセージになります:"
   ]
  },
  {
   "cell_type": "code",
   "execution_count": 2,
   "metadata": {
    "collapsed": false
   },
   "outputs": [
    {
     "ename": "ZeroDivisionError",
     "evalue": "integer division or modulo by zero",
     "output_type": "error",
     "traceback": [
      "\u001b[1;31m---------------------------------------------------------------------------\u001b[0m",
      "\u001b[1;31mZeroDivisionError\u001b[0m                         Traceback (most recent call last)",
      "\u001b[1;32m<ipython-input-2-9ce172bd90a7>\u001b[0m in \u001b[0;36m<module>\u001b[1;34m()\u001b[0m\n\u001b[1;32m----> 1\u001b[1;33m \u001b[1;36m10\u001b[0m \u001b[1;33m*\u001b[0m \u001b[1;33m(\u001b[0m\u001b[1;36m1\u001b[0m\u001b[1;33m/\u001b[0m\u001b[1;36m0\u001b[0m\u001b[1;33m)\u001b[0m\u001b[1;33m\u001b[0m\u001b[0m\n\u001b[0m",
      "\u001b[1;31mZeroDivisionError\u001b[0m: integer division or modulo by zero"
     ]
    }
   ],
   "source": [
    "10 * (1/0)"
   ]
  },
  {
   "cell_type": "code",
   "execution_count": 3,
   "metadata": {
    "collapsed": false
   },
   "outputs": [
    {
     "ename": "NameError",
     "evalue": "name 'spam' is not defined",
     "output_type": "error",
     "traceback": [
      "\u001b[1;31m---------------------------------------------------------------------------\u001b[0m",
      "\u001b[1;31mNameError\u001b[0m                                 Traceback (most recent call last)",
      "\u001b[1;32m<ipython-input-3-6b1dfe582d2e>\u001b[0m in \u001b[0;36m<module>\u001b[1;34m()\u001b[0m\n\u001b[1;32m----> 1\u001b[1;33m \u001b[1;36m4\u001b[0m \u001b[1;33m+\u001b[0m \u001b[0mspam\u001b[0m\u001b[1;33m*\u001b[0m\u001b[1;36m3\u001b[0m\u001b[1;33m\u001b[0m\u001b[0m\n\u001b[0m",
      "\u001b[1;31mNameError\u001b[0m: name 'spam' is not defined"
     ]
    }
   ],
   "source": [
    "4 + spam*3"
   ]
  },
  {
   "cell_type": "code",
   "execution_count": 4,
   "metadata": {
    "collapsed": false
   },
   "outputs": [
    {
     "ename": "TypeError",
     "evalue": "cannot concatenate 'str' and 'int' objects",
     "output_type": "error",
     "traceback": [
      "\u001b[1;31m---------------------------------------------------------------------------\u001b[0m",
      "\u001b[1;31mTypeError\u001b[0m                                 Traceback (most recent call last)",
      "\u001b[1;32m<ipython-input-4-4c6dd5170204>\u001b[0m in \u001b[0;36m<module>\u001b[1;34m()\u001b[0m\n\u001b[1;32m----> 1\u001b[1;33m \u001b[1;34m'2'\u001b[0m \u001b[1;33m+\u001b[0m \u001b[1;36m2\u001b[0m\u001b[1;33m\u001b[0m\u001b[0m\n\u001b[0m",
      "\u001b[1;31mTypeError\u001b[0m: cannot concatenate 'str' and 'int' objects"
     ]
    }
   ],
   "source": [
    "'2' + 2"
   ]
  },
  {
   "cell_type": "markdown",
   "metadata": {},
   "source": [
    "エラーメッセージの最終行は何が起こったかを示しています。例外は様々な型 (type) で起こり、その型がエラーメッセージの一部として出力されます。上の例での型は ZeroDivisionError, NameError, TypeError です。例外型として出力される文字列は、発生した例外の組み込み名です。これは全ての組み込み例外について成り立ちますが、ユーザ定義の例外では (成り立つようにするのは有意義な慣習ですが) 必ずしも成り立ちません。標準例外の名前は組み込みの識別子です (予約語ではありません)。\n",
    "\n",
    "残りの行は例外の詳細で、その例外の型と何が起きたかに依存します。\n",
    "\n",
    "エラーメッセージの先頭部分では、例外が発生した実行コンテキスト (context) を、スタックのトレースバック (stack traceback) の形式で示しています。一般には、この部分にはソースコード行をリストしたトレースバックが表示されます。しかし、標準入力から読み取られたコードは表示されません。\n",
    "\n",
    "組み込み例外 には、組み込み例外とその意味がリストされています。"
   ]
  },
  {
   "cell_type": "markdown",
   "metadata": {},
   "source": [
    "## 8.3. 例外を処理する\n",
    "例外を選別して処理するようなプログラムを書くことができます。以下の例を見てください。この例では、有効な文字列が入力されるまでユーザに入力を促しますが、ユーザがプログラムに (Control-C か、またはオペレーティングシステムがサポートしている何らかのキーを使って) 割り込みをかけてプログラムを中断させることができるようにしています。ユーザが生成した割り込みは、 KeyboardInterrupt 例外が送出されることで通知されるということに注意してください。"
   ]
  },
  {
   "cell_type": "code",
   "execution_count": 5,
   "metadata": {
    "collapsed": false
   },
   "outputs": [
    {
     "name": "stdout",
     "output_type": "stream",
     "text": [
      "Please enter a number: \n",
      "Oops!  That was no valid number.  Try again...\n",
      "Please enter a number: AAA\n",
      "Oops!  That was no valid number.  Try again...\n",
      "Please enter a number: 3\n"
     ]
    }
   ],
   "source": [
    "while True:\n",
    "    try:\n",
    "        x = int(raw_input(\"Please enter a number: \"))\n",
    "        break\n",
    "    except ValueError:\n",
    "        print \"Oops!  That was no valid number.  Try again...\""
   ]
  },
  {
   "cell_type": "markdown",
   "metadata": {},
   "source": [
    "try 文は下記のように動作します。\n",
    "\n",
    "+ まず、 try 節 (try clause) (キーワード try と except の間の文) が実行されます。\n",
    "\n",
    "\n",
    "+ 何も例外が発生しなければ、 except 節 をスキップして try 文の実行を終えます。\n",
    "\n",
    "\n",
    "+ try 節内の実行中に例外が発生すると、その節の残りは飛ばされます。次に、例外型が except キーワードの後に指定されている例外に一致する場合、except 節が実行された後、 try 文の後ろへ実行が継続されます。\n",
    "\n",
    "\n",
    "+ もしも except 節で指定された例外と一致しない例外が発生すると、その例外は try 文の外側に渡されます。例外に対するハンドラ (handler、処理部) がどこにもなければ、 処理されない例外 (unhandled exception) となり、上記に示したようなメッセージを出して実行を停止します。\n",
    "\n",
    "\n",
    "一つの try 文に複数の except 節を設けて、さまざまな例外に対するハンドラを指定することができます。同時に一つ以上のハンドラが実行されることはありません。ハンドラは対応する try 節内で発生した例外だけを処理し、同じ try 文内の別の例外ハンドラで起きた例外は処理しません。 except 節には複数の例外を丸括弧で囲ったタプルにして渡すことができます。例えば以下のようにします:"
   ]
  },
  {
   "cell_type": "code",
   "execution_count": 6,
   "metadata": {
    "collapsed": true
   },
   "outputs": [],
   "source": [
    "try:\n",
    "    pass\n",
    "except (RuntimeError, TypeError, NameError):\n",
    "    pass"
   ]
  },
  {
   "cell_type": "markdown",
   "metadata": {},
   "source": [
    "このタプルの周囲の括弧は必要です。というのも、 except ValueError, e: はモダンな Python で普通 except ValueError as e: と書く(後述)のと同じ意味のかつての文法でした。この古い文法は後方互換のために今でも残されています。つまり except RuntimeError, TypeError は except (RuntimeError, TypeError): と同じではなく、お望みのものとは違う except RuntimeError as TypeError: だということです。\n",
    "\n",
    "最後の except 節では例外名を省いて、ワイルドカード (wildcard、総称記号) にすることができます。ワイルドカードの except 節は非常に注意して使ってください。というのは、ワイルドカードは通常のプログラムエラーをたやすく隠してしまうからです！ワイルドカードの except 節はエラーメッセージを出力した後に例外を再送出する (関数やメソッドの呼び出し側が同様にして例外を処理できるようにする) 用途にも使えます:"
   ]
  },
  {
   "cell_type": "code",
   "execution_count": 7,
   "metadata": {
    "collapsed": false
   },
   "outputs": [
    {
     "name": "stdout",
     "output_type": "stream",
     "text": [
      "Could not convert data to an integer.\n"
     ]
    }
   ],
   "source": [
    "import sys\n",
    "\n",
    "try:\n",
    "    f = open('myfile.txt')\n",
    "    s = f.readline()\n",
    "    i = int(s.strip())\n",
    "except IOError as e:\n",
    "    print \"I/O error({0}): {1}\".format(e.errno, e.strerror)\n",
    "except ValueError:\n",
    "    print \"Could not convert data to an integer.\"\n",
    "except:\n",
    "    print \"Unexpected error:\", sys.exc_info()[0]\n",
    "    raise"
   ]
  },
  {
   "cell_type": "markdown",
   "metadata": {},
   "source": [
    "try ... except 文には、オプションで else 節 (else clause) を設けることができます。 else 節を設ける場合、全ての except 節よりも後ろに置かなければなりません。 else 節は try 節で全く例外が送出されなかったときに実行されるコードを書くのに役立ちます。例えば次のようにします:"
   ]
  },
  {
   "cell_type": "code",
   "execution_count": 8,
   "metadata": {
    "collapsed": false
   },
   "outputs": [
    {
     "name": "stdout",
     "output_type": "stream",
     "text": [
      "workfile.txt has 5 lines\n",
      "cannot open not_exist.txt\n"
     ]
    }
   ],
   "source": [
    "#for arg in sys.argv[1:]:\n",
    "for arg in [\"workfile.txt\", \"not_exist.txt\"]:\n",
    "    try:\n",
    "        f = open(arg, 'r')\n",
    "    except IOError:\n",
    "        print 'cannot open', arg\n",
    "    else:\n",
    "        print arg, 'has', len(f.readlines()), 'lines'\n",
    "        f.close()"
   ]
  },
  {
   "cell_type": "markdown",
   "metadata": {},
   "source": [
    "追加のコードを追加するのは try 節の後ろよりも else 節の方がよいでしょう。なぜなら、そうすることで try ... except 文で保護したいコードから送出されたもの以外の例外を偶然に捕捉してしまうという事態を避けられるからです。\n",
    "\n",
    "例外が発生するとき、例外は関連付けられた値を持つことができます。この値は例外の 引数 (argument) とも呼ばれます。引数の有無および引数の型は、例外の型に依存します。\n",
    "\n",
    "except 節では、例外名 (または例外名タプル) の後に変数を指定することができます。この変数は例外インスタンスに結び付けられており、 instance.args に例外インスタンス生成時の引数が入っています。例外インスタンスには __str__() が定義されており、 .args を参照しなくても引数を直接印字できるように利便性が図られています。\n",
    "\n",
    "必要なら、例外を送出する前にインスタンス化して、任意の属性を追加できます。"
   ]
  },
  {
   "cell_type": "code",
   "execution_count": 9,
   "metadata": {
    "collapsed": false
   },
   "outputs": [
    {
     "name": "stdout",
     "output_type": "stream",
     "text": [
      "<type 'exceptions.Exception'>\n",
      "('spam', 'eggs')\n",
      "('spam', 'eggs')\n",
      "x = spam\n",
      "y = eggs\n"
     ]
    }
   ],
   "source": [
    "try:\n",
    "   raise Exception('spam', 'eggs')\n",
    "except Exception as inst:\n",
    "   print type(inst)     # the exception instance\n",
    "   print inst.args      # arguments stored in .args\n",
    "   print inst           # __str__ allows args to be printed directly\n",
    "   x, y = inst.args\n",
    "   print 'x =', x\n",
    "   print 'y =', y"
   ]
  },
  {
   "cell_type": "markdown",
   "metadata": {},
   "source": [
    "例外が引数を持っていれば、それらは処理されない例外のメッセージの最後の部分 (「詳細説明」) に出力されます。\n",
    "\n",
    "例外ハンドラは、try 節の直接内側で発生した例外を処理するだけではなく、その try 節から (たとえ間接的にでも) 呼び出された関数の内部で発生した例外も処理します。例えば:"
   ]
  },
  {
   "cell_type": "code",
   "execution_count": 10,
   "metadata": {
    "collapsed": false
   },
   "outputs": [
    {
     "name": "stdout",
     "output_type": "stream",
     "text": [
      "Handling run-time error: integer division or modulo by zero\n"
     ]
    }
   ],
   "source": [
    "def this_fails():\n",
    "    x = 1/0\n",
    "\n",
    "try:\n",
    "    this_fails()\n",
    "except ZeroDivisionError as detail:\n",
    "    print 'Handling run-time error:', detail"
   ]
  },
  {
   "cell_type": "markdown",
   "metadata": {},
   "source": [
    "## 8.4. 例外を送出する\n",
    "raise 文を使って、特定の例外を発生させることができます。例えば:"
   ]
  },
  {
   "cell_type": "code",
   "execution_count": 11,
   "metadata": {
    "collapsed": false
   },
   "outputs": [
    {
     "ename": "NameError",
     "evalue": "HiThere",
     "output_type": "error",
     "traceback": [
      "\u001b[1;31m---------------------------------------------------------------------------\u001b[0m",
      "\u001b[1;31mNameError\u001b[0m                                 Traceback (most recent call last)",
      "\u001b[1;32m<ipython-input-11-93385ba972b1>\u001b[0m in \u001b[0;36m<module>\u001b[1;34m()\u001b[0m\n\u001b[1;32m----> 1\u001b[1;33m \u001b[1;32mraise\u001b[0m \u001b[0mNameError\u001b[0m\u001b[1;33m(\u001b[0m\u001b[1;34m'HiThere'\u001b[0m\u001b[1;33m)\u001b[0m\u001b[1;33m\u001b[0m\u001b[0m\n\u001b[0m",
      "\u001b[1;31mNameError\u001b[0m: HiThere"
     ]
    }
   ],
   "source": [
    "raise NameError('HiThere')"
   ]
  },
  {
   "cell_type": "markdown",
   "metadata": {},
   "source": [
    "raise は送出したい例外を引数として取ります。これは例外クラス(Exception を継承したクラス)か、例外クラスのインスタンスです。\n",
    "\n",
    "例外が発生したかどうかを判定したいだけで、その例外を処理するつもりがなければ、単純な形式の raise 文を使って例外を再送出させることができます:"
   ]
  },
  {
   "cell_type": "code",
   "execution_count": 12,
   "metadata": {
    "collapsed": false
   },
   "outputs": [
    {
     "name": "stdout",
     "output_type": "stream",
     "text": [
      "An exception flew by!\n"
     ]
    },
    {
     "ename": "NameError",
     "evalue": "HiThere",
     "output_type": "error",
     "traceback": [
      "\u001b[1;31m---------------------------------------------------------------------------\u001b[0m",
      "\u001b[1;31mNameError\u001b[0m                                 Traceback (most recent call last)",
      "\u001b[1;32m<ipython-input-12-e6256f74f78e>\u001b[0m in \u001b[0;36m<module>\u001b[1;34m()\u001b[0m\n\u001b[0;32m      1\u001b[0m \u001b[1;32mtry\u001b[0m\u001b[1;33m:\u001b[0m\u001b[1;33m\u001b[0m\u001b[0m\n\u001b[1;32m----> 2\u001b[1;33m     \u001b[1;32mraise\u001b[0m \u001b[0mNameError\u001b[0m\u001b[1;33m(\u001b[0m\u001b[1;34m'HiThere'\u001b[0m\u001b[1;33m)\u001b[0m\u001b[1;33m\u001b[0m\u001b[0m\n\u001b[0m\u001b[0;32m      3\u001b[0m \u001b[1;32mexcept\u001b[0m \u001b[0mNameError\u001b[0m\u001b[1;33m:\u001b[0m\u001b[1;33m\u001b[0m\u001b[0m\n\u001b[0;32m      4\u001b[0m     \u001b[1;32mprint\u001b[0m \u001b[1;34m'An exception flew by!'\u001b[0m\u001b[1;33m\u001b[0m\u001b[0m\n\u001b[0;32m      5\u001b[0m     \u001b[1;32mraise\u001b[0m\u001b[1;33m\u001b[0m\u001b[0m\n",
      "\u001b[1;31mNameError\u001b[0m: HiThere"
     ]
    }
   ],
   "source": [
    "try:\n",
    "    raise NameError('HiThere')\n",
    "except NameError:\n",
    "    print 'An exception flew by!'\n",
    "    raise"
   ]
  },
  {
   "cell_type": "markdown",
   "metadata": {},
   "source": [
    "## 8.5. ユーザー定義例外\n",
    "プログラム上で新しい例外クラスを作成することで、独自の例外を指定することができます (Python のクラスについては クラス 参照)。例外は、典型的に Exception クラスから、直接または間接的に派生したものです。例を示します:"
   ]
  },
  {
   "cell_type": "code",
   "execution_count": 13,
   "metadata": {
    "collapsed": false
   },
   "outputs": [
    {
     "name": "stdout",
     "output_type": "stream",
     "text": [
      "My exception occurred, value: 4\n"
     ]
    },
    {
     "ename": "MyError",
     "evalue": "'oops!'",
     "output_type": "error",
     "traceback": [
      "\u001b[1;31m---------------------------------------------------------------------------\u001b[0m",
      "\u001b[1;31mMyError\u001b[0m                                   Traceback (most recent call last)",
      "\u001b[1;32m<ipython-input-13-c6927389d43e>\u001b[0m in \u001b[0;36m<module>\u001b[1;34m()\u001b[0m\n\u001b[0;32m     10\u001b[0m     \u001b[1;32mprint\u001b[0m \u001b[1;34m'My exception occurred, value:'\u001b[0m\u001b[1;33m,\u001b[0m \u001b[0me\u001b[0m\u001b[1;33m.\u001b[0m\u001b[0mvalue\u001b[0m\u001b[1;33m\u001b[0m\u001b[0m\n\u001b[0;32m     11\u001b[0m \u001b[1;33m\u001b[0m\u001b[0m\n\u001b[1;32m---> 12\u001b[1;33m \u001b[1;32mraise\u001b[0m \u001b[0mMyError\u001b[0m\u001b[1;33m(\u001b[0m\u001b[1;34m'oops!'\u001b[0m\u001b[1;33m)\u001b[0m\u001b[1;33m\u001b[0m\u001b[0m\n\u001b[0m",
      "\u001b[1;31mMyError\u001b[0m: 'oops!'"
     ]
    }
   ],
   "source": [
    "class MyError(Exception):\n",
    "    def __init__(self, value):\n",
    "        self.value = value\n",
    "    def __str__(self):\n",
    "        return repr(self.value)\n",
    "\n",
    "try:\n",
    "    raise MyError(2*2)\n",
    "except MyError as e:\n",
    "    print 'My exception occurred, value:', e.value\n",
    "\n",
    "raise MyError('oops!')"
   ]
  },
  {
   "cell_type": "markdown",
   "metadata": {},
   "source": [
    "この例では Exception のデフォルト \\_\\_init\\_\\_() がオーバーライドされています。新しい振る舞いでは、単に value 属性を作ります。これは、デフォルトの args 属性を作成する振る舞いを置き換えています。\n",
    "\n",
    "例外クラスでは、普通のクラスができることなら何でも定義することができますが、通常は単純なものにしておきます。大抵は、いくつかの属性だけを提供し、例外が発生したときにハンドラがエラーに関する情報を取り出せるようにする程度にとどめます。複数の別個の例外を送出するようなモジュールを作成する際には、そのモジュールで定義されている例外の基底クラスを作成するのが一般的なプラクティスです:"
   ]
  },
  {
   "cell_type": "code",
   "execution_count": 14,
   "metadata": {
    "collapsed": false
   },
   "outputs": [],
   "source": [
    "class Error(Exception):\n",
    "    \"\"\"Base class for exceptions in this module.\"\"\"\n",
    "    pass\n",
    "\n",
    "class InputError(Error):\n",
    "    \"\"\"Exception raised for errors in the input.\n",
    "\n",
    "    Attributes:\n",
    "        expr -- input expression in which the error occurred\n",
    "        msg  -- explanation of the error\n",
    "    \"\"\"\n",
    "\n",
    "    def __init__(self, expr, msg):\n",
    "        self.expr = expr\n",
    "        self.msg = msg\n",
    "\n",
    "class TransitionError(Error):\n",
    "    \"\"\"Raised when an operation attempts a state transition that's not\n",
    "    allowed.\n",
    "\n",
    "    Attributes:\n",
    "        prev -- state at beginning of transition\n",
    "        next -- attempted new state\n",
    "        msg  -- explanation of why the specific transition is not allowed\n",
    "    \"\"\"\n",
    "\n",
    "    def __init__(self, prev, next, msg):\n",
    "        self.prev = prev\n",
    "        self.next = next\n",
    "        self.msg = msg"
   ]
  },
  {
   "cell_type": "markdown",
   "metadata": {},
   "source": [
    "ほとんどの例外は、標準の例外の名前付けと同様に、 “Error” で終わる名前で定義されています。\n",
    "\n",
    "多くの標準モジュールでは、モジュールで定義されている関数内で発生する可能性のあるエラーを報告させるために、独自の例外を定義しています。クラスについての詳細な情報は クラス 章で提供されています。"
   ]
  },
  {
   "cell_type": "markdown",
   "metadata": {},
   "source": [
    "## 8.6. クリーンアップ動作を定義する\n",
    "try 文にはもう一つオプションの節があります。この節はクリーンアップ動作を定義するためのもので、どんな状況でも必ず実行されます。例を示します:"
   ]
  },
  {
   "cell_type": "code",
   "execution_count": 15,
   "metadata": {
    "collapsed": false
   },
   "outputs": [
    {
     "name": "stdout",
     "output_type": "stream",
     "text": [
      "Goodbye, world!\n"
     ]
    },
    {
     "ename": "KeyboardInterrupt",
     "evalue": "",
     "output_type": "error",
     "traceback": [
      "\u001b[1;31m---------------------------------------------------------------------------\u001b[0m",
      "\u001b[1;31mKeyboardInterrupt\u001b[0m                         Traceback (most recent call last)",
      "\u001b[1;32m<ipython-input-15-550c84a268c5>\u001b[0m in \u001b[0;36m<module>\u001b[1;34m()\u001b[0m\n\u001b[0;32m      1\u001b[0m \u001b[1;32mtry\u001b[0m\u001b[1;33m:\u001b[0m\u001b[1;33m\u001b[0m\u001b[0m\n\u001b[1;32m----> 2\u001b[1;33m     \u001b[1;32mraise\u001b[0m \u001b[0mKeyboardInterrupt\u001b[0m\u001b[1;33m\u001b[0m\u001b[0m\n\u001b[0m\u001b[0;32m      3\u001b[0m \u001b[1;32mfinally\u001b[0m\u001b[1;33m:\u001b[0m\u001b[1;33m\u001b[0m\u001b[0m\n\u001b[0;32m      4\u001b[0m     \u001b[1;32mprint\u001b[0m \u001b[1;34m'Goodbye, world!'\u001b[0m\u001b[1;33m\u001b[0m\u001b[0m\n\u001b[0;32m      5\u001b[0m \u001b[1;33m\u001b[0m\u001b[0m\n",
      "\u001b[1;31mKeyboardInterrupt\u001b[0m: "
     ]
    }
   ],
   "source": [
    "try:\n",
    "    raise KeyboardInterrupt\n",
    "finally:\n",
    "    print 'Goodbye, world!'\n",
    "\n",
    "KeyboardInterrupt"
   ]
  },
  {
   "cell_type": "markdown",
   "metadata": {},
   "source": [
    "finally 節 (finally clause) は、例外が発生したかどうかに関わらず、 try 文を抜ける前に常に実行されます。 try 節の中で例外が発生して、 except 節で処理されていない場合、または except 節か else 節で例外が発生した場合は、 finally 節を実行した後、その例外を再送出します。 finally 節はまた、 try 節から break 文や continue 文、 return 文経由で抜ける際にも、 “抜ける途中で” 実行されます。より複雑な例です (except 節や finally 節が同じ try 文の中にあって、 Python 2.5 以降で動作します)。"
   ]
  },
  {
   "cell_type": "code",
   "execution_count": 16,
   "metadata": {
    "collapsed": false
   },
   "outputs": [
    {
     "name": "stdout",
     "output_type": "stream",
     "text": [
      "result is 2\n",
      "executing finally clause\n",
      "\n",
      "division by zero!\n",
      "executing finally clause\n",
      "\n",
      "executing finally clause\n"
     ]
    },
    {
     "ename": "TypeError",
     "evalue": "unsupported operand type(s) for /: 'str' and 'str'",
     "output_type": "error",
     "traceback": [
      "\u001b[1;31m---------------------------------------------------------------------------\u001b[0m",
      "\u001b[1;31mTypeError\u001b[0m                                 Traceback (most recent call last)",
      "\u001b[1;32m<ipython-input-16-de9d292d6cda>\u001b[0m in \u001b[0;36m<module>\u001b[1;34m()\u001b[0m\n\u001b[0;32m     15\u001b[0m \u001b[1;32mprint\u001b[0m\u001b[1;33m\u001b[0m\u001b[0m\n\u001b[0;32m     16\u001b[0m \u001b[1;33m\u001b[0m\u001b[0m\n\u001b[1;32m---> 17\u001b[1;33m \u001b[0mdivide\u001b[0m\u001b[1;33m(\u001b[0m\u001b[1;34m\"2\"\u001b[0m\u001b[1;33m,\u001b[0m \u001b[1;34m\"1\"\u001b[0m\u001b[1;33m)\u001b[0m\u001b[1;33m\u001b[0m\u001b[0m\n\u001b[0m",
      "\u001b[1;32m<ipython-input-16-de9d292d6cda>\u001b[0m in \u001b[0;36mdivide\u001b[1;34m(x, y)\u001b[0m\n\u001b[0;32m      1\u001b[0m \u001b[1;32mdef\u001b[0m \u001b[0mdivide\u001b[0m\u001b[1;33m(\u001b[0m\u001b[0mx\u001b[0m\u001b[1;33m,\u001b[0m \u001b[0my\u001b[0m\u001b[1;33m)\u001b[0m\u001b[1;33m:\u001b[0m\u001b[1;33m\u001b[0m\u001b[0m\n\u001b[0;32m      2\u001b[0m     \u001b[1;32mtry\u001b[0m\u001b[1;33m:\u001b[0m\u001b[1;33m\u001b[0m\u001b[0m\n\u001b[1;32m----> 3\u001b[1;33m         \u001b[0mresult\u001b[0m \u001b[1;33m=\u001b[0m \u001b[0mx\u001b[0m \u001b[1;33m/\u001b[0m \u001b[0my\u001b[0m\u001b[1;33m\u001b[0m\u001b[0m\n\u001b[0m\u001b[0;32m      4\u001b[0m     \u001b[1;32mexcept\u001b[0m \u001b[0mZeroDivisionError\u001b[0m\u001b[1;33m:\u001b[0m\u001b[1;33m\u001b[0m\u001b[0m\n\u001b[0;32m      5\u001b[0m         \u001b[1;32mprint\u001b[0m \u001b[1;34m\"division by zero!\"\u001b[0m\u001b[1;33m\u001b[0m\u001b[0m\n",
      "\u001b[1;31mTypeError\u001b[0m: unsupported operand type(s) for /: 'str' and 'str'"
     ]
    }
   ],
   "source": [
    "def divide(x, y):\n",
    "    try:\n",
    "        result = x / y\n",
    "    except ZeroDivisionError:\n",
    "        print \"division by zero!\"\n",
    "    else:\n",
    "        print \"result is\", result\n",
    "    finally:\n",
    "        print \"executing finally clause\"\n",
    "\n",
    "divide(2, 1)\n",
    "print\n",
    "\n",
    "divide(2, 0)\n",
    "print\n",
    "\n",
    "divide(\"2\", \"1\")"
   ]
  },
  {
   "cell_type": "markdown",
   "metadata": {},
   "source": [
    "見てわかるとおり、 finally 節はどの場合にも実行されています。文字列を割り算することで発生した TypeError は except 節で処理されていないので、 finally 節実行後に再度送出されています。\n",
    "\n",
    "実世界のアプリケーションでは、 finally 節は(ファイルやネットワーク接続などの)外部リソースを、利用が成功したかどうかにかかわらず解放するために便利です。"
   ]
  },
  {
   "cell_type": "markdown",
   "metadata": {},
   "source": [
    "## 8.7. 定義済みクリーンアップ処理\n",
    "オブジェクトのなかには、その利用の成否にかかわらず、不要になった際に実行される標準的なクリーンアップ処理が定義されているものがあります。以下の、ファイルをオープンして内容を画面に表示する例をみてください。"
   ]
  },
  {
   "cell_type": "code",
   "execution_count": 17,
   "metadata": {
    "collapsed": false
   },
   "outputs": [
    {
     "name": "stdout",
     "output_type": "stream",
     "text": [
      "33x\n"
     ]
    }
   ],
   "source": [
    "for line in open(\"myfile.txt\"):\n",
    "    print line,"
   ]
  },
  {
   "cell_type": "markdown",
   "metadata": {},
   "source": [
    "このコードの問題点は、コードの実行が終わった後に不定の時間ファイルを開いたままでいることです。これは単純なスクリプトでは問題になりませんが、大きなアプリケーションでは問題になりえます。 with 文はファイルのようなオブジェクトが常に、即座に正しくクリーンアップされることを保証します。"
   ]
  },
  {
   "cell_type": "code",
   "execution_count": 18,
   "metadata": {
    "collapsed": false
   },
   "outputs": [
    {
     "name": "stdout",
     "output_type": "stream",
     "text": [
      "33x\n"
     ]
    }
   ],
   "source": [
    "with open(\"myfile.txt\") as f:\n",
    "    for line in f:\n",
    "        print line,"
   ]
  },
  {
   "cell_type": "markdown",
   "metadata": {},
   "source": [
    "この文が実行されたあとで、たとえ行の処理中に問題があったとしても、ファイル f は常に close されます。ファイルなどの、定義済みクリーンアップ処理を持つオブジェクトについては、それぞれのドキュメントで示されます。"
   ]
  }
 ],
 "metadata": {
  "kernelspec": {
   "display_name": "Python 2",
   "language": "python",
   "name": "python2"
  },
  "language_info": {
   "codemirror_mode": {
    "name": "ipython",
    "version": 2
   },
   "file_extension": ".py",
   "mimetype": "text/x-python",
   "name": "python",
   "nbconvert_exporter": "python",
   "pygments_lexer": "ipython2",
   "version": "2.7.11"
  }
 },
 "nbformat": 4,
 "nbformat_minor": 0
}
